Failure # 1 (occurred at 2024-09-27_13-40-31)
[36mray::ImplicitFunc.train()[39m (pid=72489, ip=10.64.32.126, actor_id=dd2edb3cdbf38d8e7271110901000000, repr=custom_dqn_train)
           ^^^^^^^^^^^^^^^^^^^^^^^^^^^^^^^^^^^^
           ^^^^^^^^^^^^^^^^^^^^^^^^^^^^^^^
  File "/userhome/cs2/u3637311/anaconda3/envs/rl_env/lib/python3.12/site-packages/ray/tune/trainable/trainable.py", line 331, in train
    raise skipped from exception_cause(skipped)
  File "/userhome/cs2/u3637311/anaconda3/envs/rl_env/lib/python3.12/site-packages/ray/air/_internal/util.py", line 104, in run
    self._ret = self._target(*self._args, **self._kwargs)
                ^^^^^^^^^^^^^^^^^^^^^^^^^^^^^^^^^^^^^^^^^
  File "/userhome/cs2/u3637311/anaconda3/envs/rl_env/lib/python3.12/site-packages/ray/tune/trainable/function_trainable.py", line 45, in <lambda>
    training_func=lambda: self._trainable_func(self.config),
                          ^^^^^^^^^^^^^^^^^^^^^^^^^^^^^^^^^
           ^^^^^^^^^^^^^^^^^^^^^^^^^^^^^^^
  File "/userhome/cs2/u3637311/anaconda3/envs/rl_env/lib/python3.12/site-packages/ray/tune/trainable/function_trainable.py", line 250, in _trainable_func
    output = fn()
             ^^^^
  File "/userhome/cs2/u3637311/pytorch-ddpg/Trainer.py", line 28, in custom_dqn_train
    results = next(custom_execution_plan(workers, dqn_algo))
              ^^^^^^^^^^^^^^^^^^^^^^^^^^^^^^^^^^^^^^^^^^^^^^
TypeError: 'dict' object is not an iterator
